Workbook

Sheet Premissas
A1: VitalRise — Premissas do modelo (USD)
A2: Edite só as células em azul com fundo amarelo. Preto = fórmula; verde = link de outra aba. Cada premissa tem um rótulo: "fonte: código" (lib/products.ts e scripts do site), "conferir" (confirmar na conta do cliente) ou "HIPÓTESE: substituir por dados reais".
A3: Premissa | B3: Valor | C3: Unidade | D3: Fonte / status | E3: Observação (de onde vem, onde conferir)
A4: 1. Preços em USD (lib/products.ts → PRICES.usd, valores em centavos ÷ 100)
A5: Preço — 1 unidade | B5: 29.9 | C5: US$ por pedido | D5: fonte: código | E5: PRICES.usd.single = 2990
A6: Preço — Kit 3 (pagamento único, ciclo de 90 dias) | B6: 80 | C6: US$ por pedido | D6: fonte: código | E6: PRICES.usd.kit3 = 8000
A7: Preço — Kit 6 (estoque de 6 meses) | B7: 140 | C7: US$ por pedido | D7: fonte: código | E7: PRICES.usd.kit6 = 14000. Compra única ou assinatura pelo mesmo preço, que renova a cada 6 meses.
A8: Preço — order bump (+1 unidade no checkout) | B8: 19.9 | C8: US$ por pedido | D8: fonte: código | E8: PRICES.usd.bump = 1990 (ORDER_BUMP)
A9: Preço — upsell 1: Kit 6 pagamento único (45% off) | B9: 77 | C9: US$ por aceite | D9: fonte: código | E9: PRICES.usd.upsellKit6 = 7700 (UPSELL_KIT6)
A10: Preço — upsell 2: assinatura Kit 3 a cada 3 meses (30% off) | B10: 56 | C10: US$ por cobrança (a cada 3 meses) | D10: fonte: código | E10: PRICES.usd.upsellSub = 5600 (UPSELL_SUBSCRIPTION, recorrência de 3 meses)
A11: 2. Unidades por cobrança (para o custo do produto)
A12: Unidades — 1 unidade | B12: 1 | C12: unidades | D12: fonte: código | E12: PLANS.single.units = 1
A13: Unidades — Kit 3 | B13: 3 | C13: unidades | D13: fonte: código | E13: PLANS.kit3.units = 3
A14: Unidades — Kit 6 | B14: 6 | C14: unidades | D14: fonte: código | E14: PLANS.kit6.units = 6 (estoque de 6 meses)
A15: Unidades — order bump | B15: 1 | C15: unidades | D15: fonte: código | E15: lib/i18n/en.ts cart.bumpTitle: "+1 extra unit"
A16: Unidades — upsell 1 (Kit 6 único) | B16: 6 | C16: unidades | D16: fonte: código | E16: UPSELL_KIT6 = Kit 6 pagamento único
A17: Unidades — upsell 2 (Kit 3 por cobrança) | B17: 3 | C17: unidades por cobrança | D17: fonte: código | E17: UPSELL_SUBSCRIPTION = Kit 3 a cada 3 meses
A18: 3. Cupom VITAL10
A19: Desconto do cupom VITAL10 | B19: 0.1 | C19: % da 1ª cobrança | D19: fonte: código | E19: scripts/stripe-setup.ts: percent_off 10, duration "once" (só o 1º pagamento). Upsells são cobranças separadas e não recebem o cupom.
A20: O cupom também desconta o order bump? (1 = sim, 0 = não) | B20: 1 | C20: chave 0/1 | D20: fonte: código | E20: O cupom é criado sem applies_to, então o Stripe desconta todos os itens da sessão (plano + bump). Atenção: o carrinho (components/checkout/CheckoutFlow.tsx) mostra o desconto só sobre o plano — alinhar.
A21: % dos pedidos que usam o cupom | B21: 0.4 | C21: % dos pedidos | D21: HIPÓTESE: substituir por dados reais | E21: Medir no Stripe: Checkout Sessions com desconto (total_details.amount_discount > 0). A tabela orders não guarda o cupom.
A22: 4. Mix de planos e take rates
A23: Mix — pedidos de 1 unidade | B23: 0.2 | C23: % dos pedidos | D23: HIPÓTESE: substituir por dados reais | E23: Supabase orders.plan = 'single'
A24: Mix — pedidos de Kit 3 | B24: 0.55 | C24: % dos pedidos | D24: HIPÓTESE: substituir por dados reais | E24: orders.plan = 'kit3'. O quiz recomenda Kit 3 para quem não é persona sênior (lib/quiz.ts, recommendedPlan).
A25: Mix — pedidos de Kit 6 | B25: 0.25 | C25: % dos pedidos | D25: HIPÓTESE: substituir por dados reais | E25: orders.plan = 'kit6' (compra única ou assinatura). Recomendado para a persona sênior.
A26: Verificação: soma do mix (deve dar 100%) | B26: =SUM($B$23,$B$24,$B$25) | D26: =IF(ABS($B$26-1)<0.0001,"OK","AJUSTAR: soma ≠ 100%") | E26: Fórmula de checagem (não editar).
A27: Take rate do order bump | B27: 0.25 | C27: % dos pedidos | D27: HIPÓTESE: substituir por dados reais | E27: orders.bump = true ÷ pedidos. O bump aparece para todos os planos.
A28: Take rate do upsell 1 (Kit 6 único) | B28: 0.15 | C28: % de quem vê os upsells | D28: HIPÓTESE: substituir por dados reais | E28: Base: compradores de compra única de 1 unidade ou Kit 3. Quem assina qualquer plano ou compra o Kit 6 vai direto para /thank-you (app/api/checkout/route.ts). Evento upsell_accepted com offer = kit6.
A29: Take rate do upsell 2 (assinatura Kit 3) | B29: 0.1 | C29: % de quem vê os upsells | D29: HIPÓTESE: substituir por dados reais | E29: Mesma base. O upsell 2 aparece depois do upsell 1, aceito ou recusado (components/checkout/UpsellOffer.tsx). Evento upsell_accepted com offer = subscription.
A30: 5. Retenção das assinaturas (só para o LTV)
A31: Assinatura do plano — cobranças pagas por assinante (média, inclui a 1ª) | B31: 1 | C31: cobranças | D31: HIPÓTESE: substituir por dados reais | E31: 1 = conta só a 1ª cobrança (conservador). Vale para os três planos (1 un. todo mês, Kit 3 a cada 3 meses, Kit 6 a cada 6 meses). Substituir pela média real do Stripe: faturas pagas por assinatura dos prices STRIPE_PRICE_*_SUB.
A32: Upsell 2 — cobranças pagas por assinante (média, inclui a 1ª) | B32: 1 | C32: cobranças | D32: HIPÓTESE: substituir por dados reais | E32: Idem, price STRIPE_PRICE_UPSELL_SUB.
A33: 6. Custos variáveis — PREENCHER (vazio = as fórmulas mostram "preencha o custo")
A34: Custo do produto por unidade (COGS) | C34: US$ por unidade | D34: HIPÓTESE: substituir por dados reais | E34: VAZIO — preencher com o custo real por unidade entregue pelo fornecedor (produto + embalagem). Formato: só o número, em US$.
A35: Frete por envio (pacote) | C35: US$ por envio | D35: HIPÓTESE: substituir por dados reais | E35: VAZIO — preencher com o custo médio real de frete por pacote (com entrega em até 2 dias úteis). O frete é grátis para o cliente: todo esse custo é da empresa. Formato: só o número, em US$.
A36: Separação e embalagem por envio (opcional) | C36: US$ por envio | D36: HIPÓTESE: substituir por dados reais | E36: Opcional: taxa do operador logístico por pacote. Vazio = 0.
A37: O upsell 1 sai em envio separado? (1 = sim, 0 = mesmo pacote) | B37: 1 | C37: chave 0/1 | D37: HIPÓTESE: substituir por dados reais | E37: 1 = conservador (um frete a mais). O order bump sempre vai no mesmo pacote do pedido. Cada renovação de assinatura (do plano ou do upsell 2) conta como um envio.
A38: 7. Pagamentos (Stripe, conta nos EUA)
A39: Taxa percentual por cobrança de cartão | B39: 0.029 | C39: % do valor cobrado | D39: conferir | E39: Tarifa padrão de cartão nos EUA; confirmar na conta do cliente (Stripe → Settings → Pricing).
A40: Taxa fixa por cobrança de cartão | B40: 0.3 | C40: US$ por cobrança | D40: conferir | E40: Cada cobrança paga a taxa fixa: o pedido, o upsell 1 e cada renovação das assinaturas.
...

Sheet Unit economics
A1: VitalRise — Unit economics por comprador (USD) | F1: Margem por produto (1 cobrança, sem cupom, reembolso ou disputa)
A2: Base: 1 comprador = 1 pedido pago no checkout. Assinaturas entram só com a 1ª cobrança; a recorrência fica na seção 4 (LTV). Nenhum número aqui é digitado: tudo vem da aba Premissas.
A3: Indicador | B3: Valor | C3: Unidade | D3: Como é calculado | F3: Produto | G3: Preço | H3: Unidades | I3: COGS | J3: Frete + separação | K3: Taxas Stripe | L3: Margem | M3: Margem %
A4: Custos preenchidos? | B4: =IF(AND(ISNUMBER(Premissas!$B$34),ISNUMBER(Premissas!$B$35)),"sim","não — preencha o custo do produto e o frete na aba Premissas") | D4: Enquanto o custo do produto (COGS) ou o frete estiverem vazios, os resultados que dependem deles mostram "preencha o custo" em vez de um número enganoso. | F4: 1 unidade | G4: =Premissas!$B$5 | H4: =Premissas!$B$12 | I4: =IF(ISNUMBER(Premissas!$B$34),H4*Premissas!$B$34,"preencha o custo") | J4: =IF(ISNUMBER(Premissas!$B$35),1*(Premissas!$B$35+N(Premissas!$B$36)),"preencha o custo") | K4: =G4*(Premissas!$B$39+Premissas!$B$42)+1*Premissas!$B$40 | L4: =IF(AND(ISNUMBER(I4),ISNUMBER(J4)),G4-I4-J4-K4,"preencha o custo") | M4: =IF(ISNUMBER(L4),IF(G4>0,L4/G4,0),"preencha o custo")
A5: Mix de planos soma 100%? | B5: =IF(ABS(Premissas!$B$26-1)<0.0001,"sim","não — ajuste o mix na aba Premissas") | D5: Checagem do mix de planos. | F5: Kit 3 | G5: =Premissas!$B$6 | H5: =Premissas!$B$13 | I5: =IF(ISNUMBER(Premissas!$B$34),H5*Premissas!$B$34,"preencha o custo") | J5: =IF(ISNUMBER(Premissas!$B$35),1*(Premissas!$B$35+N(Premissas!$B$36)),"preencha o custo") | K5: =G5*(Premissas!$B$39+Premissas!$B$42)+1*Premissas!$B$40 | L5: =IF(AND(ISNUMBER(I5),ISNUMBER(J5)),G5-I5-J5-K5,"preencha o custo") | M5: =IF(ISNUMBER(L5),IF(G5>0,L5/G5,0),"preencha o custo")
A6: 1. Receita da 1ª compra (por comprador) | F6: Kit 6 | G6: =Premissas!$B$7 | H6: =Premissas!$B$14 | I6: =IF(ISNUMBER(Premissas!$B$34),H6*Premissas!$B$34,"preencha o custo") | J6: =IF(ISNUMBER(Premissas!$B$35),1*(Premissas!$B$35+N(Premissas!$B$36)),"preencha o custo") | K6: =G6*(Premissas!$B$39+Premissas!$B$42)+1*Premissas!$B$40 | L6: =IF(AND(ISNUMBER(I6),ISNUMBER(J6)),G6-I6-J6-K6,"preencha o custo") | M6: =IF(ISNUMBER(L6),IF(G6>0,L6/G6,0),"preencha o custo")
A7: Preço médio do plano (pelo mix) | B7: =Premissas!$B$23*Premissas!$B$5+Premissas!$B$24*Premissas!$B$6+Premissas!$B$25*Premissas!$B$7 | C7: US$ por comprador | D7: Σ (participação no mix × preço). O preço é o mesmo na compra única e na assinatura. | F7: Order bump (mesmo pacote) | G7: =Premissas!$B$8 | H7: =Premissas!$B$15 | I7: =IF(ISNUMBER(Premissas!$B$34),H7*Premissas!$B$34,"preencha o custo") | J7: =IF(ISNUMBER(Premissas!$B$35),0*(Premissas!$B$35+N(Premissas!$B$36)),"preencha o custo") | K7: =G7*(Premissas!$B$39+Premissas!$B$42)+0*Premissas!$B$40 | L7: =IF(AND(ISNUMBER(I7),ISNUMBER(J7)),G7-I7-J7-K7,"preencha o custo") | M7: =IF(ISNUMBER(L7),IF(G7>0,L7/G7,0),"preencha o custo")
A8: Receita do order bump | B8: =Premissas!$B$27*Premissas!$B$8 | C8: US$ por comprador | D8: Take rate do bump × preço do bump. | F8: Upsell 1 — Kit 6 único | G8: =Premissas!$B$9 | H8: =Premissas!$B$16 | I8: =IF(ISNUMBER(Premissas!$B$34),H8*Premissas!$B$34,"preencha o custo") | J8: =IF(ISNUMBER(Premissas!$B$35),Premissas!$B$37*(Premissas!$B$35+N(Premissas!$B$36)),"preencha o custo") | K8: =G8*(Premissas!$B$39+Premissas!$B$42)+1*Premissas!$B$40 | L8: =IF(AND(ISNUMBER(I8),ISNUMBER(J8)),G8-I8-J8-K8,"preencha o custo") | M8: =IF(ISNUMBER(L8),IF(G8>0,L8/G8,0),"preencha o custo")
A9: Subtotal do checkout antes do cupom | B9: =$B$7+$B$8 | C9: US$ por comprador | D9: Plano médio + bump. | F9: Upsell 2 — Kit 3 (cada cobrança) | G9: =Premissas!$B$10 | H9: =Premissas!$B$17 | I9: =IF(ISNUMBER(Premissas!$B$34),H9*Premissas!$B$34,"preencha o custo") | J9: =IF(ISNUMBER(Premissas!$B$35),1*(Premissas!$B$35+N(Premissas!$B$36)),"preencha o custo") | K9: =G9*(Premissas!$B$39+Premissas!$B$42+Premissas!$B$41)+1*Premissas!$B$40 | L9: =IF(AND(ISNUMBER(I9),ISNUMBER(J9)),G9-I9-J9-K9,"preencha o custo") | M9: =IF(ISNUMBER(L9),IF(G9>0,L9/G9,0),"preencha o custo")
A10: (−) Desconto do cupom VITAL10 | B10: =Premissas!$B$21*Premissas!$B$19*($B$7+Premissas!$B$20*$B$8) | C10: US$ por comprador | D10: % de pedidos com cupom × 10% × (plano + bump, se o cupom incidir no bump). | F10: O bump não paga frete nem taxa fixa (vai no mesmo pacote e na mesma cobrança). Na assinatura soma-se o Stripe Billing (Premissas B41). Margem negativa no produto de 1 unidade é comum quando o frete (grátis para o cliente) é alto — confira com os custos reais.
A11: Ticket médio do pedido (AOV) | B11: =$B$9-$B$10 | C11: US$ por pedido | D11: Valor cobrado no checkout. É o que vai em orders.amount_cents e no value do evento purchase.
A12: Compradores que veem os upsells (compra única de 1 unidade ou Kit 3) | B12: =(Premissas!$B$23+Premissas!$B$24)*(1-Premissas!$B$64) | C12: % dos compradores | D12: Quem assina qualquer plano ou compra o Kit 6 pula os upsells (success_url vai direto para /thank-you).
A13: Receita do upsell 1 (Kit 6 único) | B13: =$B$12*Premissas!$B$28*Premissas!$B$9 | C13: US$ por comprador | D13: % que vê os upsells × take rate do upsell 1 × preço.
A14: Receita do upsell 2 (1ª cobrança da assinatura) | B14: =$B$12*Premissas!$B$29*Premissas!$B$10 | C14: US$ por comprador | D14: % que vê os upsells × take rate do upsell 2 × preço da cobrança (a cada 3 meses).
A15: Receita bruta por comprador (1ª compra) | B15: =$B$11+$B$13+$B$14 | C15: US$ por comprador | D15: Pedido + upsells (1ª cobrança). É a receita que aparece no Stripe.
A16: (−) Reembolsos | B16: =Premissas!$B$45*$B$15 | C16: US$ por comprador | D16: Taxa de reembolso × receita bruta.
A17: (−) Valores perdidos em disputas | B17: =Premissas!$B$46*$B$11 | C17: US$ por comprador | D17: Taxa de disputas × ticket médio.
A18: Receita líquida por comprador | B18: =$B$15-$B$16-$B$17 | C18: US$ por comprador | D18: Receita bruta − reembolsos − disputas.
A19: 2. Custos variáveis por comprador (1ª compra)
A20: Unidades enviadas por comprador | B20: =Premissas!$B$23*Premissas!$B$12+Premissas!$B$24*Premissas!$B$13+Premissas!$B$25*Premissas!$B$14+Premissas!$B$27*Premissas!$B$15+$B$12*Premissas!$B$28*Premissas!$B$16+$B$12*Premissas!$B$29*Premissas!$B$17 | C20: unidades | D20: Plano + bump + upsells (1ª entrega da assinatura do upsell 2).
A21: Envios por comprador | B21: =1+$B$12*Premissas!$B$28*Premissas!$B$37+$B$12*Premissas!$B$29 | C21: envios | D21: 1 pacote do pedido (com o bump) + upsell 1 se for separado + 1ª entrega do upsell 2.
A22: Cobranças no cartão por comprador | B22: =1+$B$12*Premissas!$B$28+$B$12*Premissas!$B$29 | C22: cobranças | D22: Pedido + cada upsell aceito (cada um paga a taxa fixa do Stripe).
A23: Volume de assinatura na 1ª cobrança (base do Stripe Billing) | B23: =Premissas!$B$64*$B$7*(1-Premissas!$B$21*Premissas!$B$19)+$B$14 | C23: US$ por comprador | D23: 1ª cobrança das assinaturas do plano (com cupom) + 1ª cobrança do upsell 2. Aproximação: ignora o bump na fatura da assinatura.
A24: Custo do produto (COGS) | B24: =IF(ISNUMBER(Premissas!$B$34),$B$20*Premissas!$B$34,"preencha o custo") | C24: US$ por comprador | D24: Unidades × custo por unidade.
A25: Frete + separação | B25: =IF(ISNUMBER(Premissas!$B$35),$B$21*(Premissas!$B$35+N(Premissas!$B$36)),"preencha o custo") | C25: US$ por comprador | D25: Envios × (frete + separação/embalagem).
A26: Taxas de cartão do Stripe | B26: =$B$15*(Premissas!$B$39+Premissas!$B$42)+$B$22*Premissas!$B$40 | C26: US$ por comprador | D26: Receita bruta × (taxa % + adicional internacional) + cobranças × taxa fixa. Não volta no reembolso.
A27: Stripe Billing (assinaturas) | B27: =$B$23*Premissas!$B$41 | C27: US$ por comprador | D27: Volume de assinatura × taxa do Billing.
A28: Taxas de disputa | B28: =Premissas!$B$46*Premissas!$B$43 | C28: US$ por comprador | D28: Taxa de disputas × taxa por disputa.
A29: Custos variáveis totais | B29: =IF($B$4<>"sim","preencha o custo",$B$24+$B$25+$B$26+$B$27+$B$28) | C29: US$ por comprador | D29: COGS + frete + Stripe + Billing + disputas.
A30: 3. Margem de contribuição e limites de mídia (1ª compra)
A31: Margem de contribuição por comprador (antes da mídia) | B31: =IF($B$4<>"sim","preencha o custo",$B$18-$B$29) | C31: US$ por comprador | D31: Receita líquida − custos variáveis. Não inclui custos fixos nem impostos.
A32: Margem de contribuição (% da receita líquida) | B32: =IF($B$4<>"sim","preencha o custo",IF($B$18>0,$B$31/$B$18,0)) | C32: % | D32: Margem de contribuição ÷ receita líquida.
A33: CPA de equilíbrio (custo máximo por compra) | B33: =IF($B$4<>"sim","preencha o custo",$B$31) | C33: US$ por compra | D33: Pagando este valor de mídia por compra, a 1ª compra empata (lucro zero).
A34: CPA alvo (na margem-alvo) | B34: =IF($B$4<>"sim","preencha o custo",$B$31-Premissas!$B$48*$B$18) | C34: US$ por compra | D34: Margem de contribuição − margem-alvo × receita líquida. Negativo = a margem-alvo não cabe nesses preços/custos.
A35: ROAS de equilíbrio — receita total no Stripe | B35: =IF($B$4<>"sim","preencha o custo",IF($B$33>0,$B$15/$B$33,"sem margem (CPA ≤ 0)")) | C35: receita ÷ gasto | D35: Receita bruta ÷ CPA de equilíbrio. Comparar com receita do Stripe (pedido + upsells) ÷ gasto.
A36: ROAS de equilíbrio — valor do Pixel (só o pedido) | B36: =IF($B$4<>"sim","preencha o custo",IF($B$33>0,$B$11/$B$33,"sem margem (CPA ≤ 0)")) | C36: receita ÷ gasto | D36: Ticket médio ÷ CPA de equilíbrio. Comparar com o "Purchase ROAS" do Meta, que não inclui os upsells.
A37: ROAS alvo — receita total no Stripe | B37: =IF($B$4<>"sim","preencha o custo",IF($B$34>0,$B$15/$B$34,"sem margem (CPA ≤ 0)")) | C37: receita ÷ gasto | D37: Receita bruta ÷ CPA alvo.
A38: ROAS alvo — valor do Pixel (só o pedido) | B38: =IF($B$4<>"sim","preencha o custo",IF($B$34>0,$B$11/$B$34,"sem margem (CPA ≤ 0)")) | C38: receita ÷ gasto | D38: Ticket médio ÷ CPA alvo.
A39: 4. LTV com a retenção das assinaturas (opcional; com retenção = 1 é igual à 1ª compra)
A40: Cobranças extras das assinaturas do plano por comprador | B40: =Premissas!$B$64*MAX(Premissas!$B$31-1,0) | C40: cobranças | D40: % de assinantes × (cobranças por assinante − 1).
...

Sheet Funil
A1: VitalRise — Funil por 1.000 visitantes
A2: As taxas vêm da aba Premissas (seções 4 e 10, em verde). Quantidades, receita e limites de custo são calculados. Eventos GA4/PostHog/Meta saem de lib/analytics.ts e só disparam após o consentimento de cookies.
A3: Etapa | B3: Evento GA4 / PostHog | C3: Evento Meta Pixel | D3: Taxa da etapa | E3: Base da taxa | F3: Quantidade por 1.000 visitantes | G3: % dos visitantes | H3: Fonte de verdade para a contagem real
A4: Visitantes na landing (/quiz) | B4: page_view em /quiz (GA4) · $pageview (PostHog) | C4: PageView | D4: — | E4: — | F4: =Premissas!$B$50 | G4: =IF($F$4>0,F4/$F$4,0) | H4: GA4: sessões com landing page /quiz; Meta: Landing page views (Ads Manager)
A5: Início do quiz | B5: quiz_start | C5: quiz_start (trackCustom) | D5: =Premissas!$B$52 | E5: sobre visitantes | F5: =$F$4*D5 | G5: =IF($F$4>0,F5/$F$4,0) | H5: GA4/PostHog quiz_start
A6: Quiz concluído | B6: quiz_complete (persona_gender, age) | C6: Lead | D6: =Premissas!$B$53 | E6: sobre início do quiz | F6: =$F$5*D6 | G6: =IF($F$4>0,F6/$F$4,0) | H6: Supabase quiz_responses (linha criada em /analyzing; não depende de cookies)
A7: Oferta vista | B7: view_offer (persona) | C7: ViewContent | D7: =Premissas!$B$54 | E7: sobre quiz concluído | F7: =$F$6*D7 | G7: =IF($F$4>0,F7/$F$4,0) | H7: GA4/PostHog view_offer
A8: Início do checkout | B8: begin_checkout (plan, value, currency) | C8: InitiateCheckout | D8: =Premissas!$B$55 | E8: sobre oferta vista | F8: =$F$7*D8 | G8: =IF($F$4>0,F8/$F$4,0) | H8: GA4/PostHog begin_checkout
A9: Compra | B9: purchase (value, currency, plan) | C9: Purchase | D9: =Premissas!$B$56 | E9: sobre início do checkout | F9: =$F$8*D9 | G9: =IF($F$4>0,F9/$F$4,0) | H9: Stripe checkout.session.completed (pago) · Supabase orders (status = 'paid')
A10: Pedidos com order bump | B10: — (sem evento próprio) | C10: — | D10: =Premissas!$B$27 | E10: sobre compras | F10: =$F$9*D10 | G10: =IF($F$4>0,F10/$F$4,0) | H10: Supabase orders.bump = true
A11: Compradores que veem os upsells (compra única de 1 unidade ou Kit 3) | B11: — (página /upsell-1) | C11: — | D11: ='Unit economics'!$B$12 | E11: sobre compras (mix de planos) | F11: =$F$9*D11 | G11: =IF($F$4>0,F11/$F$4,0) | H11: Supabase orders.plan in ('single', 'kit3'), só compra única (Stripe: mode payment)
A12: Upsell 1 aceito (Kit 6 único) | B12: upsell_accepted (offer = kit6) | C12: upsell_accepted (trackCustom) | D12: =Premissas!$B$28 | E12: sobre quem vê os upsells | F12: =$F$11*D12 | G12: =IF($F$4>0,F12/$F$4,0) | H12: Stripe PaymentIntents com metadata upsell = kit6 · Supabase orders.upsells
A13: Upsell 2 aceito (assinatura Kit 3) | B13: upsell_accepted (offer = subscription) | C13: upsell_accepted (trackCustom) | D13: =Premissas!$B$29 | E13: sobre quem vê os upsells | F13: =$F$11*D13 | G13: =IF($F$4>0,F13/$F$4,0) | H13: Stripe Subscriptions com metadata upsell = subscription
A15: Receita e limites de custo de mídia por 1.000 visitantes
A16: Indicador | B16: Valor | C16: Como é calculado
A17: Conversão visitante → compra | B17: =IF($F$4>0,$F$9/$F$4,0) | C17: Compras ÷ visitantes.
A18: Receita bruta por comprador (1ª compra) | B18: ='Unit economics'!$B$15 | C18: Da aba Unit economics (pedido + upsells).
A19: Receita bruta por 1.000 visitantes | B19: =$F$9*$B$18 | C19: Compras × receita bruta por comprador.
A20: Receita por visitante (RPV) | B20: =IF($F$4>0,$B$19/$F$4,0) | C20: Receita ÷ visitantes.
A21: Margem de contribuição por comprador | B21: ='Unit economics'!$B$31 | C21: Da aba Unit economics (antes da mídia).
A22: Margem de contribuição por 1.000 visitantes (antes da mídia) | B22: =IF(ISNUMBER($B$21),$F$9*$B$21,"preencha o custo") | C22: É o máximo que se pode gastar em mídia para trazer estes visitantes sem prejuízo na 1ª compra.
A23: Margem de contribuição por visitante | B23: =IF(ISNUMBER($B$22),IF($F$4>0,$B$22/$F$4,0),"preencha o custo") | C23: Custo máximo por visita na landing.
A24: CPC máximo de equilíbrio (por clique no link) | B24: =IF(ISNUMBER($B$23),$B$23*Premissas!$B$51,"preencha o custo") | C24: Margem por visitante × taxa clique → visita. Acima disso a 1ª compra dá prejuízo.
A25: CPC máximo na margem-alvo | B25: =IF(ISNUMBER('Unit economics'!$B$34),IF($F$4>0,$F$9*'Unit economics'!$B$34/$F$4*Premissas!$B$51,0),"preencha o custo") | C25: Compras × CPA alvo ÷ visitantes × taxa clique → visita.
A26: CPM máximo de equilíbrio (com o CTR da meta) | B26: =IF(ISNUMBER($B$24),$B$24*Premissas!$B$58*1000,"preencha o custo") | C26: CPC de equilíbrio × CTR da meta × 1.000 impressões.
A27: Custo máximo por quiz concluído (equilíbrio) | B27: =IF(ISNUMBER($B$22),IF($F$6>0,$B$22/$F$6,0),"preencha o custo") | C27: Margem por 1.000 visitantes ÷ quizzes concluídos. Compare com o custo por Lead do Meta.
A28: Custo máximo por quiz concluído (margem-alvo) | B28: =IF(ISNUMBER('Unit economics'!$B$34),IF($F$6>0,$F$9*'Unit economics'!$B$34/$F$6,0),"preencha o custo") | C28: Compras × CPA alvo ÷ quizzes concluídos.
A29: CPA de equilíbrio (referência) | B29: ='Unit economics'!$B$33 | C29: Da aba Unit economics.
A30: CPC máximo de equilíbrio pelo LTV | B30: =IF(ISNUMBER('Unit economics'!$B$47),IF($F$4>0,$F$9*'Unit economics'!$B$47/$F$4*Premissas!$B$51,0),"preencha o custo") | C30: Igual ao CPC de equilíbrio, usando o LTV de margem (retenção da aba Premissas).

Sheet KPIs
A1: VitalRise — KPIs do funil, metas e alertas
A2: Metas em verde vêm das Premissas (hipóteses) ou do cálculo do modelo. Preencha "Valor medido" na cadência indicada; o status compara com a meta e o limite de alerta. Valores percentuais como fração (0,25 = 25%).
A3: # | B3: KPI | C3: Definição | D3: Evento / fonte exata | E3: Fórmula | F3: Direção | G3: Meta | H3: Limite de alerta | I3: Cadência de revisão | J3: Valor medido (preencher) | K3: Status | L3: Origem da meta
A4: Mídia
A5: 1 | B5: CTR do link | C5: Cliques no link ÷ impressões do anúncio. | D5: Meta Ads Manager: "Link clicks" e "Impressions"; TikTok Ads Manager: "Clicks" e "Impressions". | E5: cliques no link ÷ impressões | F5: maior melhor | G5: =Premissas!$B$58 | H5: =G5*Premissas!$B$61 | I5: Diária, por criativo | K5: =IF(J5="","—",IF(OR(NOT(ISNUMBER(G5)),NOT(ISNUMBER(H5))),"meta pendente: preencha o custo",IF(F5="maior melhor",IF(J5<H5,"ALERTA",IF(J5<G5,"abaixo da meta","OK")),IF(J5>H5,"ALERTA",IF(J5>G5,"acima da meta","OK"))))) | L5: Premissas §11 (HIPÓTESE)
A6: 2 | B6: Taxa clique → visita | C6: Visitas que carregam a landing ÷ cliques no link. | D6: Meta Ads Manager: "Landing page views" ÷ "Link clicks". | E6: landing page views ÷ link clicks | F6: maior melhor | G6: =Premissas!$B$51 | H6: =G6*Premissas!$B$61 | I6: Diária | K6: =IF(J6="","—",IF(OR(NOT(ISNUMBER(G6)),NOT(ISNUMBER(H6))),"meta pendente: preencha o custo",IF(F6="maior melhor",IF(J6<H6,"ALERTA",IF(J6<G6,"abaixo da meta","OK")),IF(J6>H6,"ALERTA",IF(J6>G6,"acima da meta","OK"))))) | L6: Premissas §10 (HIPÓTESE)
A7: 3 | B7: CPC do link | C7: Gasto ÷ cliques no link. | D7: Meta/TikTok Ads Manager: "Amount spent" e "Link clicks". | E7: gasto ÷ cliques no link | F7: menor melhor | G7: =Funil!$B$25 | H7: =Funil!$B$24 | I7: Diária | K7: =IF(J7="","—",IF(OR(NOT(ISNUMBER(G7)),NOT(ISNUMBER(H7))),"meta pendente: preencha o custo",IF(F7="maior melhor",IF(J7<H7,"ALERTA",IF(J7<G7,"abaixo da meta","OK")),IF(J7>H7,"ALERTA",IF(J7>G7,"acima da meta","OK"))))) | L7: Funil: CPC na margem-alvo; alerta = CPC de equilíbrio
A8: 4 | B8: Custo por quiz concluído | C8: Gasto ÷ quizzes concluídos. | D8: Gasto: Ads Manager. Quizzes: Supabase quiz_responses (contagem no período) ou evento Lead do Meta. | E8: gasto ÷ count(quiz_responses) | F8: menor melhor | G8: =Funil!$B$28 | H8: =Funil!$B$27 | I8: Diária | K8: =IF(J8="","—",IF(OR(NOT(ISNUMBER(G8)),NOT(ISNUMBER(H8))),"meta pendente: preencha o custo",IF(F8="maior melhor",IF(J8<H8,"ALERTA",IF(J8<G8,"abaixo da meta","OK")),IF(J8>H8,"ALERTA",IF(J8>G8,"acima da meta","OK"))))) | L8: Funil: margem-alvo; alerta = equilíbrio
A9: 5 | B9: CPA (custo por compra) | C9: Gasto ÷ compras pagas. | D9: Gasto: Ads Manager. Compras: Stripe (Checkout Sessions pagas, sem metadata upsell) ou Supabase orders (status = 'paid'). | E9: gasto ÷ count(orders) | F9: menor melhor | G9: ='Unit economics'!$B$34 | H9: ='Unit economics'!$B$33 | I9: Diária; decisão de escala semanal | K9: =IF(J9="","—",IF(OR(NOT(ISNUMBER(G9)),NOT(ISNUMBER(H9))),"meta pendente: preencha o custo",IF(F9="maior melhor",IF(J9<H9,"ALERTA",IF(J9<G9,"abaixo da meta","OK")),IF(J9>H9,"ALERTA",IF(J9>G9,"acima da meta","OK"))))) | L9: Unit economics: CPA alvo; alerta = CPA de equilíbrio
A10: 6 | B10: ROAS — receita do Stripe | C10: Receita bruta da 1ª compra (pedido + upsells) ÷ gasto. | D10: Stripe: cobranças do período (pedidos + PaymentIntents/Subscriptions com metadata upsell). Gasto: Ads Manager. | E10: receita bruta Stripe ÷ gasto | F10: maior melhor | G10: ='Unit economics'!$B$37 | H10: ='Unit economics'!$B$35 | I10: Semanal | K10: =IF(J10="","—",IF(OR(NOT(ISNUMBER(G10)),NOT(ISNUMBER(H10))),"meta pendente: preencha o custo",IF(F10="maior melhor",IF(J10<H10,"ALERTA",IF(J10<G10,"abaixo da meta","OK")),IF(J10>H10,"ALERTA",IF(J10>G10,"acima da meta","OK"))))) | L10: Unit economics: ROAS alvo; alerta = ROAS de equilíbrio
A11: 7 | B11: ROAS reportado pelo Meta (Pixel) | C11: Valor dos eventos Purchase ÷ gasto. Não inclui upsells. | D11: Meta Ads Manager: "Purchase ROAS". O value do purchase é o valor do pedido (components/checkout/ThankYou.tsx). | E11: purchase value ÷ gasto | F11: maior melhor | G11: ='Unit economics'!$B$38 | H11: ='Unit economics'!$B$36 | I11: Diária | K11: =IF(J11="","—",IF(OR(NOT(ISNUMBER(G11)),NOT(ISNUMBER(H11))),"meta pendente: preencha o custo",IF(F11="maior melhor",IF(J11<H11,"ALERTA",IF(J11<G11,"abaixo da meta","OK")),IF(J11>H11,"ALERTA",IF(J11>G11,"acima da meta","OK"))))) | L11: Unit economics: ROAS alvo (Pixel); alerta = equilíbrio (Pixel)
A12: Funil
A13: 8 | B13: Início do quiz | C13: Visitantes que abrem a 1ª pergunta. | D13: GA4/PostHog: quiz_start ÷ sessões com landing /quiz. Meta: quiz_start (trackCustom). | E13: quiz_start ÷ visitantes | F13: maior melhor | G13: =Premissas!$B$52 | H13: =G13*Premissas!$B$61 | I13: Semanal | K13: =IF(J13="","—",IF(OR(NOT(ISNUMBER(G13)),NOT(ISNUMBER(H13))),"meta pendente: preencha o custo",IF(F13="maior melhor",IF(J13<H13,"ALERTA",IF(J13<G13,"abaixo da meta","OK")),IF(J13>H13,"ALERTA",IF(J13>G13,"acima da meta","OK"))))) | L13: Premissas §10 (HIPÓTESE)
A14: 9 | B14: Conclusão do quiz | C14: Quem iniciou e terminou as 8 perguntas (+ contato opcional). | D14: GA4/PostHog: quiz_complete ÷ quiz_start. Meta: Lead. Supabase: quiz_responses. | E14: quiz_complete ÷ quiz_start | F14: maior melhor | G14: =Premissas!$B$53 | H14: =G14*Premissas!$B$61 | I14: Semanal | K14: =IF(J14="","—",IF(OR(NOT(ISNUMBER(G14)),NOT(ISNUMBER(H14))),"meta pendente: preencha o custo",IF(F14="maior melhor",IF(J14<H14,"ALERTA",IF(J14<G14,"abaixo da meta","OK")),IF(J14>H14,"ALERTA",IF(J14>G14,"acima da meta","OK"))))) | L14: Premissas §10 (HIPÓTESE)
A15: 10 | B15: Oferta vista | C15: Quem concluiu o quiz e chegou à oferta (depois de /analyzing). | D15: GA4/PostHog: view_offer ÷ quiz_complete. Meta: ViewContent. | E15: view_offer ÷ quiz_complete | F15: maior melhor | G15: =Premissas!$B$54 | H15: =G15*Premissas!$B$61 | I15: Semanal | K15: =IF(J15="","—",IF(OR(NOT(ISNUMBER(G15)),NOT(ISNUMBER(H15))),"meta pendente: preencha o custo",IF(F15="maior melhor",IF(J15<H15,"ALERTA",IF(J15<G15,"abaixo da meta","OK")),IF(J15>H15,"ALERTA",IF(J15>G15,"acima da meta","OK"))))) | L15: Premissas §10 (HIPÓTESE)
A16: 11 | B16: Início do checkout | C16: Quem viu a oferta e abriu o checkout. | D16: GA4/PostHog: begin_checkout ÷ view_offer. Meta: InitiateCheckout. | E16: begin_checkout ÷ view_offer | F16: maior melhor | G16: =Premissas!$B$55 | H16: =G16*Premissas!$B$61 | I16: Semanal | K16: =IF(J16="","—",IF(OR(NOT(ISNUMBER(G16)),NOT(ISNUMBER(H16))),"meta pendente: preencha o custo",IF(F16="maior melhor",IF(J16<H16,"ALERTA",IF(J16<G16,"abaixo da meta","OK")),IF(J16>H16,"ALERTA",IF(J16>G16,"acima da meta","OK"))))) | L16: Premissas §10 (HIPÓTESE)
A17: 12 | B17: Conversão do checkout | C17: Compras pagas ÷ inícios de checkout. | D17: Compras: Stripe/Supabase orders. Inícios: GA4/PostHog begin_checkout. | E17: count(orders) ÷ begin_checkout | F17: maior melhor | G17: =Premissas!$B$56 | H17: =G17*Premissas!$B$61 | I17: Semanal | K17: =IF(J17="","—",IF(OR(NOT(ISNUMBER(G17)),NOT(ISNUMBER(H17))),"meta pendente: preencha o custo",IF(F17="maior melhor",IF(J17<H17,"ALERTA",IF(J17<G17,"abaixo da meta","OK")),IF(J17>H17,"ALERTA",IF(J17>G17,"acima da meta","OK"))))) | L17: Premissas §10 (HIPÓTESE)
A18: 13 | B18: Conversão visitante → compra | C18: Compras pagas ÷ visitantes na landing. | D18: Supabase orders ÷ GA4 sessões com landing /quiz. | E18: count(orders) ÷ visitantes | F18: maior melhor | G18: =Funil!$B$17 | H18: =G18*Premissas!$B$61 | I18: Semanal | K18: =IF(J18="","—",IF(OR(NOT(ISNUMBER(G18)),NOT(ISNUMBER(H18))),"meta pendente: preencha o custo",IF(F18="maior melhor",IF(J18<H18,"ALERTA",IF(J18<G18,"abaixo da meta","OK")),IF(J18>H18,"ALERTA",IF(J18>G18,"acima da meta","OK"))))) | L18: Funil (produto das taxas)
A19: 14 | B19: Receita por visitante (RPV) | C19: Receita bruta da 1ª compra ÷ visitantes. | D19: Receita: Stripe. Visitantes: GA4 sessões com landing /quiz. | E19: receita bruta ÷ visitantes | F19: maior melhor | G19: =Funil!$B$20 | H19: =G19*Premissas!$B$61 | I19: Semanal | K19: =IF(J19="","—",IF(OR(NOT(ISNUMBER(G19)),NOT(ISNUMBER(H19))),"meta pendente: preencha o custo",IF(F19="maior melhor",IF(J19<H19,"ALERTA",IF(J19<G19,"abaixo da meta","OK")),IF(J19>H19,"ALERTA",IF(J19>G19,"acima da meta","OK"))))) | L19: Funil (calculado)
A20: 15 | B20: Captura de e-mail no quiz | C20: Respostas do quiz com e-mail ÷ respostas. | D20: Supabase quiz_responses: count(email is not null) ÷ count(*). | E20: com e-mail ÷ total | F20: maior melhor | G20: =Premissas!$B$60 | H20: =G20*Premissas!$B$61 | I20: Semanal | K20: =IF(J20="","—",IF(OR(NOT(ISNUMBER(G20)),NOT(ISNUMBER(H20))),"meta pendente: preencha o custo",IF(F20="maior melhor",IF(J20<H20,"ALERTA",IF(J20<G20,"abaixo da meta","OK")),IF(J20>H20,"ALERTA",IF(J20>G20,"acima da meta","OK"))))) | L20: Premissas §11 (HIPÓTESE)
A21: Monetização
A22: 16 | B22: Ticket médio (AOV) | C22: Valor cobrado por pedido (após cupom, sem upsells). | D22: Supabase orders: avg(amount_cents) ÷ 100, com currency = 'usd'. Stripe: amount_total da Checkout Session. | E22: soma(amount_cents) ÷ 100 ÷ pedidos | F22: maior melhor | G22: ='Unit economics'!$B$11 | H22: =G22*Premissas!$B$61 | I22: Semanal | K22: =IF(J22="","—",IF(OR(NOT(ISNUMBER(G22)),NOT(ISNUMBER(H22))),"meta pendente: preencha o custo",IF(F22="maior melhor",IF(J22<H22,"ALERTA",IF(J22<G22,"abaixo da meta","OK")),IF(J22>H22,"ALERTA",IF(J22>G22,"acima da meta","OK"))))) | L22: Unit economics (calculado)
A23: 17 | B23: Participação de kits (Kit 3 + Kit 6) | C23: Pedidos de Kit 3 ou Kit 6 ÷ pedidos. | D23: Supabase orders.plan in ('kit3', 'kit6'). | E23: pedidos de kit ÷ pedidos | F23: maior melhor | G23: =Premissas!$B$24+Premissas!$B$25 | H23: =G23*Premissas!$B$61 | I23: Semanal | K23: =IF(J23="","—",IF(OR(NOT(ISNUMBER(G23)),NOT(ISNUMBER(H23))),"meta pendente: preencha o custo",IF(F23="maior melhor",IF(J23<H23,"ALERTA",IF(J23<G23,"abaixo da meta","OK")),IF(J23>H23,"ALERTA",IF(J23>G23,"acima da meta","OK"))))) | L23: Premissas §4 (HIPÓTESE)
A24: 18 | B24: Take rate do order bump | C24: Pedidos com o bump ÷ pedidos. | D24: Supabase orders.bump = true. | E24: count(bump) ÷ count(orders) | F24: maior melhor | G24: =Premissas!$B$27 | H24: =G24*Premissas!$B$61 | I24: Semanal | K24: =IF(J24="","—",IF(OR(NOT(ISNUMBER(G24)),NOT(ISNUMBER(H24))),"meta pendente: preencha o custo",IF(F24="maior melhor",IF(J24<H24,"ALERTA",IF(J24<G24,"abaixo da meta","OK")),IF(J24>H24,"ALERTA",IF(J24>G24,"acima da meta","OK"))))) | L24: Premissas §4 (HIPÓTESE)
A25: 19 | B25: Take rate do upsell 1 | C25: Aceites do Kit 6 único ÷ compradores de compra única de 1 unidade ou Kit 3. | D25: GA4/PostHog/Meta: upsell_accepted com offer = kit6. Stripe: PaymentIntents com metadata upsell = kit6 (inclui o caminho com 3-D Secure, que não dispara o evento). Supabase orders.upsells. | E25: aceites kit6 ÷ pedidos single/kit3 | F25: maior melhor | G25: =Premissas!$B$28 | H25: =G25*Premissas!$B$61 | I25: Semanal | K25: =IF(J25="","—",IF(OR(NOT(ISNUMBER(G25)),NOT(ISNUMBER(H25))),"meta pendente: preencha o custo",IF(F25="maior melhor",IF(J25<H25,"ALERTA",IF(J25<G25,"abaixo da meta","OK")),IF(J25>H25,"ALERTA",IF(J25>G25,"acima da meta","OK"))))) | L25: Premissas §4 (HIPÓTESE)
A26: 20 | B26: Take rate do upsell 2 | C26: Assinaturas do upsell ÷ compradores de 1 unidade ou Kit 3. | D26: GA4/PostHog/Meta: upsell_accepted com offer = subscription. Stripe: Subscriptions com metadata upsell = subscription. | E26: aceites subscription ÷ pedidos single/kit3 | F26: maior melhor | G26: =Premissas!$B$29 | H26: =G26*Premissas!$B$61 | I26: Semanal | K26: =IF(J26="","—",IF(OR(NOT(ISNUMBER(G26)),NOT(ISNUMBER(H26))),"meta pendente: preencha o custo",IF(F26="maior melhor",IF(J26<H26,"ALERTA",IF(J26<G26,"abaixo da meta","OK")),IF(J26>H26,"ALERTA",IF(J26>G26,"acima da meta","OK"))))) | L26: Premissas §4 (HIPÓTESE)
A27: 21 | B27: Uso do cupom VITAL10 | C27: Pedidos com o cupom ÷ pedidos (mais uso = menos margem que o previsto). | D27: Stripe: Checkout Sessions com promotion code VITAL10 (total_details.amount_discount > 0). | E27: pedidos com cupom ÷ pedidos | F27: menor melhor | G27: =Premissas!$B$21 | H27: =G27*Premissas!$B$62 | I27: Semanal | K27: =IF(J27="","—",IF(OR(NOT(ISNUMBER(G27)),NOT(ISNUMBER(H27))),"meta pendente: preencha o custo",IF(F27="maior melhor",IF(J27<H27,"ALERTA",IF(J27<G27,"abaixo da meta","OK")),IF(J27>H27,"ALERTA",IF(J27>G27,"acima da meta","OK"))))) | L27: Premissas §3 (HIPÓTESE)
A28: Pós-venda
A29: 22 | B29: Taxa de reembolso | C29: Valor reembolsado ÷ receita da 1ª compra (garantia de 30 dias). | D29: Stripe: Refunds / relatório de saldo. O webhook não grava reembolsos em orders.status. | E29: reembolsos ÷ receita bruta | F29: menor melhor | G29: =Premissas!$B$45 | H29: =G29*Premissas!$B$62 | I29: Semanal | K29: =IF(J29="","—",IF(OR(NOT(ISNUMBER(G29)),NOT(ISNUMBER(H29))),"meta pendente: preencha o custo",IF(F29="maior melhor",IF(J29<H29,"ALERTA",IF(J29<G29,"abaixo da meta","OK")),IF(J29>H29,"ALERTA",IF(J29>G29,"acima da meta","OK"))))) | L29: Premissas §8 (HIPÓTESE)
A30: 23 | B30: Taxa de disputas | C30: Disputas (chargebacks) ÷ pedidos. | D30: Stripe: Disputes. | E30: disputas ÷ pedidos | F30: menor melhor | G30: =Premissas!$B$46 | H30: =G30*Premissas!$B$62 | I30: Semanal | K30: =IF(J30="","—",IF(OR(NOT(ISNUMBER(G30)),NOT(ISNUMBER(H30))),"meta pendente: preencha o custo",IF(F30="maior melhor",IF(J30<H30,"ALERTA",IF(J30<G30,"abaixo da meta","OK")),IF(J30>H30,"ALERTA",IF(J30>G30,"acima da meta","OK"))))) | L30: Premissas §8 (HIPÓTESE)
A31: 24 | B31: Retenção das assinaturas | C31: Cobranças pagas por assinatura do plano (média, inclui a 1ª). | D31: Stripe: faturas pagas por assinatura dos prices STRIPE_PRICE_SINGLE_SUB, KIT3_SUB e KIT6_SUB. | E31: faturas pagas ÷ assinaturas | F31: maior melhor | G31: =Premissas!$B$31 | H31: =G31*Premissas!$B$61 | I31: Mensal | K31: =IF(J31="","—",IF(OR(NOT(ISNUMBER(G31)),NOT(ISNUMBER(H31))),"meta pendente: preencha o custo",IF(F31="maior melhor",IF(J31<H31,"ALERTA",IF(J31<G31,"abaixo da meta","OK")),IF(J31>H31,"ALERTA",IF(J31>G31,"acima da meta","OK"))))) | L31: Premissas §5 (HIPÓTESE)
A32: 25 | B32: Retenção da assinatura do upsell 2 | C32: Cobranças pagas por assinatura do upsell 2 (média, inclui a 1ª). | D32: Stripe: faturas pagas por assinatura do price STRIPE_PRICE_UPSELL_SUB. | E32: faturas pagas ÷ assinaturas | F32: maior melhor | G32: =Premissas!$B$32 | H32: =G32*Premissas!$B$61 | I32: Mensal | K32: =IF(J32="","—",IF(OR(NOT(ISNUMBER(G32)),NOT(ISNUMBER(H32))),"meta pendente: preencha o custo",IF(F32="maior melhor",IF(J32<H32,"ALERTA",IF(J32<G32,"abaixo da meta","OK")),IF(J32>H32,"ALERTA",IF(J32>G32,"acima da meta","OK"))))) | L32: Premissas §5 (HIPÓTESE)
A33: 26 | B33: Margem de contribuição após mídia | C33: (Receita líquida − custos variáveis − gasto) ÷ receita líquida. | D33: Stripe (receita, reembolsos, taxas) + custos da aba Premissas + gasto do Ads Manager. | E33: (receita líquida − custos − gasto) ÷ receita líquida | F33: maior melhor | G33: =Premissas!$B$48 | H33: 0 | I33: Semanal | K33: =IF(J33="","—",IF(OR(NOT(ISNUMBER(G33)),NOT(ISNUMBER(H33))),"meta pendente: preencha o custo",IF(F33="maior melhor",IF(J33<H33,"ALERTA",IF(J33<G33,"abaixo da meta","OK")),IF(J33>H33,"ALERTA",IF(J33>G33,"acima da meta","OK"))))) | L33: Premissas §9 (HIPÓTESE); alerta = 0% (equilíbrio)
A34: Rastreamento
A35: 27 | B35: Cobertura do rastreamento | C35: Eventos Purchase do Pixel ÷ pedidos pagos no Stripe. | D35: Meta Events Manager (Purchase) ÷ Supabase orders. Perde-se por recusa de cookies e por quem fecha a página nos upsells (purchase só dispara em /thank-you). | E35: Purchase do Pixel ÷ count(orders) | F35: maior melhor | G35: =Premissas!$B$59 | H35: =G35*Premissas!$B$61 | I35: Semanal | K35: =IF(J35="","—",IF(OR(NOT(ISNUMBER(G35)),NOT(ISNUMBER(H35))),"meta pendente: preencha o custo",IF(F35="maior melhor",IF(J35<H35,"ALERTA",IF(J35<G35,"abaixo da meta","OK")),IF(J35>H35,"ALERTA",IF(J35>G35,"acima da meta","OK"))))) | L35: Premissas §11 (HIPÓTESE)

Sheet Como usar
A1: Como usar esta planilha
A3: Antes de tudo
A4: 1 | B4: Abra a aba Premissas e preencha o custo do produto por unidade (COGS) e o frete por envio (seção 6). Enquanto estiverem vazios, margem, CPA, ROAS, CPC máximo e custo máximo por quiz mostram "preencha o custo" — de propósito, para não exibir um número enganoso.
A5: 2 | B5: Só edite células em azul com fundo amarelo. Preto = fórmula; verde = link de outra aba. Percentuais são frações: 0,25 = 25%.
A6: 3 | B6: Cada premissa tem um rótulo: "fonte: código" (preços e unidades de lib/products.ts e scripts/stripe-setup.ts — mude no código e aqui ao mesmo tempo), "conferir" (taxas do Stripe: confirmar na conta do cliente) e "HIPÓTESE: substituir por dados reais" (conversões, take rates, mix, reembolso, retenção, metas). Nenhuma hipótese é dado real: são pontos de partida para o cálculo.
A7: Como ler
A8: 4 | B8: Unit economics: receita, custos e margem de contribuição por comprador na 1ª compra (assinaturas contam só a 1ª cobrança). CPA de equilíbrio = máximo de mídia por compra sem prejuízo; CPA alvo = o que sobra para mídia mantendo a margem-alvo. Há dois ROAS: o do Stripe (pedido + upsells) e o do Pixel (só o pedido, que é o "Purchase ROAS" do Meta). A seção 4 (LTV) só muda quando a retenção for maior que 1.
A9: 5 | B9: Funil: quantidades por 1.000 visitantes em cada etapa (quiz_start → quiz_complete → view_offer → begin_checkout → purchase → upsell_accepted), receita por visitante, CPC máximo e custo máximo por quiz concluído (equilíbrio e margem-alvo). Compare o custo por quiz com o custo por Lead do Meta.
A10: 6 | B10: KPIs: uma linha por indicador, com o evento ou a tabela exata (GA4/PostHog/Meta Pixel de lib/analytics.ts, Stripe, Supabase quiz_responses/orders). Preencha "Valor medido" na cadência indicada; o Status mostra OK, abaixo/acima da meta ou ALERTA. Os limites de alerta usam as tolerâncias da seção 11 das Premissas; nos custos de mídia o alerta é o ponto de equilíbrio.
A11: Substituir hipóteses por dados
A12: 7 | B12: Quando houver vendas, troque as hipóteses pelos números medidos: mix, bump e upsells em Supabase orders; cupom, reembolsos, disputas e retenção no Stripe; taxas do funil em GA4/PostHog (eventos só contam quem aceitou cookies — use quiz_responses e orders para os totais). Troque o rótulo para a fonte real.
A13: 8 | B13: Para contar compras, use Stripe/Supabase, não o evento purchase: ele só dispara em /thank-you, depois dos upsells, e depende do consentimento de cookies. Upsells pagos via 3-D Secure não disparam upsell_accepted nem gravam orders.upsells — conte pelos metadados do Stripe.
A14: Limites do modelo
A15: 9 | B15: Não inclui custos fixos (equipe, ferramentas, hospedagem, vídeos), impostos sobre vendas, recompra do Kit 3 nem moedas fora do USD (os preços em outras moedas estão em lib/products.ts). Os reembolsos são tratados de forma conservadora: a taxa do Stripe não volta e o produto não é recuperado.
A16: 10 | B16: Divergência encontrada no código: o cupom VITAL10 é criado sem applies_to, então o Stripe desconta também o order bump, mas o carrinho (CheckoutFlow.tsx) calcula o desconto só sobre o plano. A chave "O cupom também desconta o order bump?" (Premissas §3) segue o que o Stripe cobra.
